UndefinedError
jinja2.exceptions.UndefinedError: 'now' is undefined

Traceback (most recent call last)
File "C:\Users\simba\anaconda3\Lib\site-packages\flask\app.py", line 1498, in __call__
return self.wsgi_app(environ, start_response)
       ^^^^^^^^^^^^^^^^^^^^^^^^^^^^^^^^^^^^^^
File "C:\Users\simba\anaconda3\Lib\site-packages\werkzeug\middleware\proxy_fix.py", line 183, in __call__
return self.app(environ, start_response)
       ^^^^^^^^^^^^^^^^^^^^^^^^^^^^^^^^^
File "C:\Users\simba\anaconda3\Lib\site-packages\flask\app.py", line 1476, in wsgi_app
response = self.handle_exception(e)
           ^^^^^^^^^^^^^^^^^^^^^^^^
File "C:\Users\simba\anaconda3\Lib\site-packages\flask\app.py", line 1473, in wsgi_app
response = self.full_dispatch_request()
           ^^^^^^^^^^^^^^^^^^^^^^^^^^^^
File "C:\Users\simba\anaconda3\Lib\site-packages\flask\app.py", line 882, in full_dispatch_request
rv = self.handle_user_exception(e)
     ^^^^^^^^^^^^^^^^^^^^^^^^^^^^^
File "C:\Users\simba\anaconda3\Lib\site-packages\flask\app.py", line 880, in full_dispatch_request
rv = self.dispatch_request()
     ^^^^^^^^^^^^^^^^^^^^^^^
File "C:\Users\simba\anaconda3\Lib\site-packages\flask\app.py", line 865, in dispatch_request
return self.ensure_sync(self.view_functions[rule.endpoint])(**view_args)  # type: ignore[no-any-return]
       ^^^^^^^^^^^^^^^^^^^^^^^^^^^^^^^^^^^^^^^^^^^^^^^^^^^^^^^^^^^^^^^^^
File "C:\Users\simba\Desktop\pio\CyberShieldIntelligence-main\routes\auth.py", line 60, in register
return render_template('auth/register.html', title='Register', form=form)
       ^^^^^^^^^^^^^^^^^^^^^^^^^^^^^^^^^^^^^^^^^^^^^^^^^^^^^^^^^^^^^^^^^^
File "C:\Users\simba\anaconda3\Lib\site-packages\flask\templating.py", line 150, in render_template
return _render(app, template, context)
       ^^^^^^^^^^^^^^^^^^^^^^^^^^^^^^^
File "C:\Users\simba\anaconda3\Lib\site-packages\flask\templating.py", line 131, in _render
rv = template.render(context)
     ^^^^^^^^^^^^^^^^^^^^^^^^
File "C:\Users\simba\anaconda3\Lib\site-packages\jinja2\environment.py", line 1304, in render
self.environment.handle_exception()
^^^^^^^^^^^^^^^^^^^^^^^^^^^^^^^^^^^
File "C:\Users\simba\anaconda3\Lib\site-packages\jinja2\environment.py", line 939, in handle_exception
raise rewrite_traceback_stack(source=source)
^^^^^^^^^^^^^^^^^^^^^^^^^^^^^^^^^^^^^^^^^^^^
File "C:\Users\simba\Desktop\pio\CyberShieldIntelligence-main\templates\auth\register.html", line 1, in top-level template code
{% extends "layout.html" %}
File "C:\Users\simba\Desktop\pio\CyberShieldIntelligence-main\templates\layout.html", line 56, in top-level template code
&copy; {{ now.year }} Simbarashe Chimbera. All rights reserved. | CyberTech&trade; Breach Detection System
File "C:\Users\simba\anaconda3\Lib\site-packages\jinja2\environment.py", line 487, in getattr
return getattr(obj, attribute)
       ^^^^^^^^^^^^^^^^^^^^^^^
jinja2.exceptions.UndefinedError: 'now' is undefined
The debugger caught an exception in your WSGI application. You can now look at the traceback which led to the error.
To switch between the interactive traceback and the plaintext one, you can click on the "Traceback" headline. From the text traceback you can also create a paste of it.

